Workbook

Sheet NOTAS
A2: Centro | D2: Vel max
A3: Longitud | D3: Fecha max
A4: Latitud | D4: Direccion max
A5: Inicio Medición
A6: Término Medición | D6: Indicador | E6: Vel.Viento [m/s] | F6: Racha. Viento [m/s] | G6: Dir. Viento [°] | H6: Componente U [m/s | I6: Componente V [m/s
A7: Duración [días] | B7: =B6-B5 -> 0 | D7: N° Datos
A8: Declinación Inicio [°] | D8: Máximo
A9: Declinación final [°] | D9: Mínimo
A10: Error promedio [°] | D10: Promedio
D11: Des. Estándar
D12: Mediana | G12: -
D13: Percentil 75 | G13: -
D14: Percentil 95 | G14: -
D16: Componente | E16: Máxima [m/s] | F16: Mínima [m/s] | G16: Promedio [m/s] | H16: Des. Estándar [m/s]
D17: U | E17: =$H$8 -> 0 | F17: =$H$9 -> 0 | G17: =$H$10 -> 0 | H17: =$H$11 -> 0
D18: V | E18: =$I$8 -> 0 | F18: =$I$9 -> 0 | G18: =$I$10 -> 0 | H18: =$I$11 -> 0

Sheet TABLAS_INCIDENCIA
C1: Direccion | K1: Cant. Datos | L1: Porcentaje | N1: DATOS COMPLETOS
C2: N | D2: NE | E2: E | F2: SE | G2: S | H2: SO | I2: O | J2: NO
A3: Rangos de Velocidad del Viento [m/s] | K3: =SUM(C3:J3) -> 0 | L3: =SUM(C3:J3)/$K$11 -> #DIV/0!
K4: =SUM(C4:J4) -> 0 | L4: =SUM(C4:J4)/$K$11 -> #DIV/0! | M4: =SUM(L3:L4) -> #DIV/0!
K5: =SUM(C5:J5) -> 0 | L5: =SUM(C5:J5)/$K$11 -> #DIV/0!
K6: =SUM(C6:J6) -> 0 | L6: =SUM(C6:J6)/$K$11 -> #DIV/0! | M6: =SUM(L6:L10) -> #DIV/0!
K7: =SUM(C7:J7) -> 0 | L7: =SUM(C7:J7)/$K$11 -> #DIV/0!
K8: =SUM(C8:J8) -> 0 | L8: =SUM(C8:J8)/$K$11 -> #DIV/0!
K9: =SUM(C9:J9) -> 0 | L9: =SUM(C9:J9)/$K$11 -> #DIV/0!
K10: =SUM(C10:J10) -> 0 | L10: =SUM(C10:J10)/$K$11 -> #DIV/0!
A11: Cant. Datos | C11: =SUM(C3:C10) -> 0 | D11: =SUM(D3:D10) -> 0 | E11: =SUM(E3:E10) -> 0 | F11: =SUM(F3:F10) -> 0 | G11: =SUM(G3:G10) -> 0 | H11: =SUM(H3:H10) -> 0 | I11: =SUM(I3:I10) -> 0 | J11: =SUM(J3:J10) -> 0 | ... L11: =SUM(L3:L10) -> #DIV/0!
A12: Porcentaje | C12: =C11/$K$11 -> #DIV/0! | D12: =D11/$K$11 -> #DIV/0! | E12: =E11/$K$11 -> #DIV/0! | F12: =F11/$K$11 -> #DIV/0! | G12: =G11/$K$11 -> #DIV/0! | H12: =H11/$K$11 -> #DIV/0! | I12: =I11/$K$11 -> #DIV/0! | J12: =J11/$K$11 -> #DIV/0! | K12: =SUM(C12:J12) -> #DIV/0!
A13: Velocidad [m/s] | B13: Máxima
B14: Promedio
B15: Desv. Estándar
C17: Direccion | K17: Cant. Datos | L17: Porcentaje | N17: HORA 00
C18: N | D18: NE | E18: E | F18: SE | G18: S | H18: SO | I18: O | J18: NO
A19: Rangos de Velocidad del Viento [m/s] | K19: =SUM(C19:J19) -> 0 | L19: =SUM(C19:J19)/$K$27 -> #DIV/0!
K20: =SUM(C20:J20) -> 0 | L20: =SUM(C20:J20)/$K$27 -> #DIV/0!
K21: =SUM(C21:J21) -> 0 | L21: =SUM(C21:J21)/$K$27 -> #DIV/0!
K22: =SUM(C22:J22) -> 0 | L22: =SUM(C22:J22)/$K$27 -> #DIV/0!
K23: =SUM(C23:J23) -> 0 | L23: =SUM(C23:J23)/$K$27 -> #DIV/0!
K24: =SUM(C24:J24) -> 0 | L24: =SUM(C24:J24)/$K$27 -> #DIV/0!
K25: =SUM(C25:J25) -> 0 | L25: =SUM(C25:J25)/$K$27 -> #DIV/0!
K26: =SUM(C26:J26) -> 0 | L26: =SUM(C26:J26)/$K$27 -> #DIV/0!
A27: Cant. Datos | C27: =SUM(C19:C26) -> 0 | D27: =SUM(D19:D26) -> 0 | E27: =SUM(E19:E26) -> 0 | F27: =SUM(F19:F26) -> 0 | G27: =SUM(G19:G26) -> 0 | H27: =SUM(H19:H26) -> 0 | I27: =SUM(I19:I26) -> 0 | J27: =SUM(J19:J26) -> 0 | ... L27: =SUM(L19:L26) -> #DIV/0!
A28: Porcentaje | C28: =C27/$K$27 -> #DIV/0! | D28: =D27/$K$27 -> #DIV/0! | E28: =E27/$K$27 -> #DIV/0! | F28: =F27/$K$27 -> #DIV/0! | G28: =G27/$K$27 -> #DIV/0! | H28: =H27/$K$27 -> #DIV/0! | I28: =I27/$K$27 -> #DIV/0! | J28: =J27/$K$27 -> #DIV/0! | K28: =SUM(C28:J28) -> #DIV/0!
A29: Velocidad [m/s] | B29: Máxima
B30: Promedio
B31: Desv. Estándar
C33: Direccion | K33: Cant. Datos | L33: Porcentaje | N33: HORA 04
C34: N | D34: NE | E34: E | F34: SE | G34: S | H34: SO | I34: O | J34: NO
A35: Rangos de Velocidad del Viento [m/s] | K35: =SUM(C35:J35) -> 0 | L35: =SUM(C35:J35)/$K$43 -> #DIV/0!
K36: =SUM(C36:J36) -> 0 | L36: =SUM(C36:J36)/$K$43 -> #DIV/0!
K37: =SUM(C37:J37) -> 0 | L37: =SUM(C37:J37)/$K$43 -> #DIV/0!
K38: =SUM(C38:J38) -> 0 | L38: =SUM(C38:J38)/$K$43 -> #DIV/0!
K39: =SUM(C39:J39) -> 0 | L39: =SUM(C39:J39)/$K$43 -> #DIV/0!
K40: =SUM(C40:J40) -> 0 | L40: =SUM(C40:J40)/$K$43 -> #DIV/0!
K41: =SUM(C41:J41) -> 0 | L41: =SUM(C41:J41)/$K$43 -> #DIV/0!
K42: =SUM(C42:J42) -> 0 | L42: =SUM(C42:J42)/$K$43 -> #DIV/0!
...

Sheet RESUMEN_6H
A1: Dirección | B1: Hora 00 | C1: Hora 04 | D1: Hora 08 | E1: Hora 12 | F1: Hora 16 | G1: Hora 20
A2: N | B2: =TABLAS_INCIDENCIA!$C$28 -> #DIV/0! | C2: =TABLAS_INCIDENCIA!$C$44 -> #DIV/0! | D2: =TABLAS_INCIDENCIA!$C$60 -> #DIV/0! | E2: =TABLAS_INCIDENCIA!$C$76 -> #DIV/0! | F2: =TABLAS_INCIDENCIA!$C$92 -> #DIV/0! | G2: =TABLAS_INCIDENCIA!$C$108 -> #DIV/0!
A3: NE | B3: =TABLAS_INCIDENCIA!$D$28 -> #DIV/0! | C3: =TABLAS_INCIDENCIA!$D$44 -> #DIV/0! | D3: =TABLAS_INCIDENCIA!$D$60 -> #DIV/0! | E3: =TABLAS_INCIDENCIA!$D$76 -> #DIV/0! | F3: =TABLAS_INCIDENCIA!$D$92 -> #DIV/0! | G3: =TABLAS_INCIDENCIA!$D$108 -> #DIV/0!
A4: E | B4: =TABLAS_INCIDENCIA!$E$28 -> #DIV/0! | C4: =TABLAS_INCIDENCIA!$E$44 -> #DIV/0! | D4: =TABLAS_INCIDENCIA!$E$60 -> #DIV/0! | E4: =TABLAS_INCIDENCIA!$E$76 -> #DIV/0! | F4: =TABLAS_INCIDENCIA!$E$92 -> #DIV/0! | G4: =TABLAS_INCIDENCIA!$E$108 -> #DIV/0!
A5: SE | B5: =TABLAS_INCIDENCIA!$F$28 -> #DIV/0! | C5: =TABLAS_INCIDENCIA!$F$44 -> #DIV/0! | D5: =TABLAS_INCIDENCIA!$F$60 -> #DIV/0! | E5: =TABLAS_INCIDENCIA!$F$76 -> #DIV/0! | F5: =TABLAS_INCIDENCIA!$F$92 -> #DIV/0! | G5: =TABLAS_INCIDENCIA!$F$108 -> #DIV/0!
A6: S | B6: =TABLAS_INCIDENCIA!G$28 -> #DIV/0! | C6: =TABLAS_INCIDENCIA!$G$44 -> #DIV/0! | D6: =TABLAS_INCIDENCIA!$G$60 -> #DIV/0! | E6: =TABLAS_INCIDENCIA!$G$76 -> #DIV/0! | F6: =TABLAS_INCIDENCIA!$G$92 -> #DIV/0! | G6: =TABLAS_INCIDENCIA!$G$108 -> #DIV/0!
A7: SO | B7: =TABLAS_INCIDENCIA!$H$28 -> #DIV/0! | C7: =TABLAS_INCIDENCIA!$H$44 -> #DIV/0! | D7: =TABLAS_INCIDENCIA!$H$60 -> #DIV/0! | E7: =TABLAS_INCIDENCIA!$H$76 -> #DIV/0! | F7: =TABLAS_INCIDENCIA!$H$92 -> #DIV/0! | G7: =TABLAS_INCIDENCIA!$H$108 -> #DIV/0!
A8: O | B8: =TABLAS_INCIDENCIA!$I$28 -> #DIV/0! | C8: =TABLAS_INCIDENCIA!$I$44 -> #DIV/0! | D8: =TABLAS_INCIDENCIA!$I$60 -> #DIV/0! | E8: =TABLAS_INCIDENCIA!$I$76 -> #DIV/0! | F8: =TABLAS_INCIDENCIA!$I$92 -> #DIV/0! | G8: =TABLAS_INCIDENCIA!$I$108 -> #DIV/0!
A9: NO | B9: =TABLAS_INCIDENCIA!$J$28 -> #DIV/0! | C9: =TABLAS_INCIDENCIA!$J$44 -> #DIV/0! | D9: =TABLAS_INCIDENCIA!$J$60 -> #DIV/0! | E9: =TABLAS_INCIDENCIA!$J$76 -> #DIV/0! | F9: =TABLAS_INCIDENCIA!$J$92 -> #DIV/0! | G9: =TABLAS_INCIDENCIA!$J$108 -> #DIV/0!
A10: Total | B10: =SUM(B2:B9) -> #DIV/0! | C10: =SUM(C2:C9) -> #DIV/0! | D10: =SUM(D2:D9) -> #DIV/0! | E10: =SUM(E2:E9) -> #DIV/0! | F10: =SUM(F2:F9) -> #DIV/0! | G10: =SUM(G2:G9) -> #DIV/0!

Sheet ANÁLISIS_MENSUAL
A1: Indicador | B1: NOV | C1: DIC | D1: ENE | E1: FEB | F1: MAR | G1: ABR | H1: MAY | I1: JUN | J1: JUL | K1: AGO | L1: SEP | M1: OCT | N1: NOV | O1: DIC | P1: ENE | Q1: FEB | R1: MAR | S1: ABR | T1: MAY
A2: Cantidad de Datos
A3: Máximo
A4: Mínimo
A5: Promedio
A6: Des. Estándar
A7: Mediana (Percentil 50)
A8: Percentil 5
A9: Percentil 95
B11: N° Datos | C11: Máximo | D11: Mínimo | E11: Promedio | F11: Des. Estándar | G11: Mediana | H11: Percentil 5 | I11: Percentil 95
A12: =B1 -> NOV | B12: =B2 -> 0 | C12: =B3 -> 0 | D12: =B4 -> 0 | E12: =B5 -> 0 | F12: =B6 -> 0 | G12: =B7 -> 0 | H12: =B8 -> 0 | I12: =B9 -> 0
A13: =C1 -> DIC | B13: =C2 -> 0 | C13: =C3 -> 0 | D13: =C4 -> 0 | E13: =C5 -> 0 | F13: =C6 -> 0 | G13: =C7 -> 0 | H13: =C8 -> 0 | I13: =C9 -> 0
A14: =D1 -> ENE | B14: =D2 -> 0 | C14: =D3 -> 0 | D14: =D4 -> 0 | E14: =D5 -> 0 | F14: =D6 -> 0 | G14: =D7 -> 0 | H14: =D8 -> 0 | I14: =D9 -> 0
A15: =E1 -> FEB | B15: =E2 -> 0 | C15: =E3 -> 0 | D15: =E4 -> 0 | E15: =E5 -> 0 | F15: =E6 -> 0 | G15: =E7 -> 0 | H15: =E8 -> 0 | I15: =E9 -> 0
A16: =F1 -> MAR | B16: =F2 -> 0 | C16: =F3 -> 0 | D16: =F4 -> 0 | E16: =F5 -> 0 | F16: =F6 -> 0 | G16: =F7 -> 0 | H16: =F8 -> 0 | I16: =F9 -> 0
A17: =G1 -> ABR | B17: =G2 -> 0 | C17: =G3 -> 0 | D17: =G4 -> 0 | E17: =G5 -> 0 | F17: =G6 -> 0 | G17: =G7 -> 0 | H17: =G8 -> 0 | I17: =G9 -> 0
A18: =H1 -> MAY | B18: =H2 -> 0 | C18: =H3 -> 0 | D18: =H4 -> 0 | E18: =H5 -> 0 | F18: =H6 -> 0 | G18: =H7 -> 0 | H18: =H8 -> 0 | I18: =H9 -> 0
A19: =I1 -> JUN | B19: =I2 -> 0 | C19: =I3 -> 0 | D19: =I4 -> 0 | E19: =I5 -> 0 | F19: =I6 -> 0 | G19: =I7 -> 0 | H19: =I8 -> 0 | I19: =I9 -> 0
A20: =J1 -> JUL | B20: =J2 -> 0 | C20: =J3 -> 0 | D20: =J4 -> 0 | E20: =J5 -> 0 | F20: =J6 -> 0 | G20: =J7 -> 0 | H20: =J8 -> 0 | I20: =J9 -> 0
A21: =K1 -> AGO | B21: =K2 -> 0 | C21: =K3 -> 0 | D21: =K4 -> 0 | E21: =K5 -> 0 | F21: =K6 -> 0 | G21: =K7 -> 0 | H21: =K8 -> 0 | I21: =K9 -> 0
A22: =L1 -> SEP | B22: =L2 -> 0 | C22: =L3 -> 0 | D22: =L4 -> 0 | E22: =L5 -> 0 | F22: =L6 -> 0 | G22: =L7 -> 0 | H22: =L8 -> 0 | I22: =L9 -> 0
A23: =M1 -> OCT | B23: =M2 -> 0 | C23: =M3 -> 0 | D23: =M4 -> 0 | E23: =M5 -> 0 | F23: =M6 -> 0 | G23: =M7 -> 0 | H23: =M8 -> 0 | I23: =M9 -> 0
A24: =N1 -> NOV | B24: =N2 -> 0 | C24: =N3 -> 0 | D24: =N4 -> 0 | E24: =N5 -> 0 | F24: =N6 -> 0 | G24: =N7 -> 0 | H24: =N8 -> 0 | I24: =N9 -> 0
A25: =O1 -> DIC | B25: =O2 -> 0 | C25: =O3 -> 0 | D25: =O4 -> 0 | E25: =O5 -> 0 | F25: =O6 -> 0 | G25: =O7 -> 0 | H25: =O8 -> 0 | I25: =O9 -> 0
A26: =P1 -> ENE | B26: =P2 -> 0 | C26: =P3 -> 0 | D26: =P4 -> 0 | E26: =P5 -> 0 | F26: =P6 -> 0 | G26: =P7 -> 0 | H26: =P8 -> 0 | I26: =P9 -> 0
A27: =Q1 -> FEB | B27: =Q2 -> 0 | C27: =Q3 -> 0 | D27: =Q4 -> 0 | E27: =Q5 -> 0 | F27: =Q6 -> 0 | G27: =Q7 -> 0 | H27: =Q8 -> 0 | I27: =Q9 -> 0
A28: =R1 -> MAR | B28: =R2 -> 0 | C28: =R3 -> 0 | D28: =R4 -> 0 | E28: =R5 -> 0 | F28: =R6 -> 0 | G28: =R7 -> 0 | H28: =R8 -> 0 | I28: =R9 -> 0
A29: =S1 -> ABR | B29: =S2 -> 0 | C29: =S3 -> 0 | D29: =S4 -> 0 | E29: =S5 -> 0 | F29: =S6 -> 0 | G29: =S7 -> 0 | H29: =S8 -> 0 | I29: =S9 -> 0
A30: =T1 -> MAY | B30: =T2 -> 0 | C30: =T3 -> 0 | D30: =T4 -> 0 | E30: =T5 -> 0 | F30: =T6 -> 0 | G30: =T7 -> 0 | H30: =T8 -> 0 | I30: =T9 -> 0

Sheet TABLAS_INCIDENCIA_MENSUAL
C1: Direccion | K1: Cant. Datos | L1: Porcentaje
C2: N | D2: NE | E2: E | F2: SE | G2: S | H2: SO | I2: O | J2: NO
A3: Rangos de Velocidad del Viento [m/s] | K3: =SUM(C3:J3) -> 0 | L3: =SUM(C3:J3)/$K$11 -> #DIV/0!
K4: =SUM(C4:J4) -> 0 | L4: =SUM(C4:J4)/$K$11 -> #DIV/0! | N4: marzo
K5: =SUM(C5:J5) -> 0 | L5: =SUM(C5:J5)/$K$11 -> #DIV/0!
K6: =SUM(C6:J6) -> 0 | L6: =SUM(C6:J6)/$K$11 -> #DIV/0!
K7: =SUM(C7:J7) -> 0 | L7: =SUM(C7:J7)/$K$11 -> #DIV/0!
K8: =SUM(C8:J8) -> 0 | L8: =SUM(C8:J8)/$K$11 -> #DIV/0!
K9: =SUM(C9:J9) -> 0 | L9: =SUM(C9:J9)/$K$11 -> #DIV/0!
K10: =SUM(C10:J10) -> 0 | L10: =SUM(C10:J10)/$K$11 -> #DIV/0!
A11: Cant. Datos | C11: =SUM(C3:C10) -> 0 | D11: =SUM(D3:D10) -> 0 | E11: =SUM(E3:E10) -> 0 | F11: =SUM(F3:F10) -> 0 | G11: =SUM(G3:G10) -> 0 | H11: =SUM(H3:H10) -> 0 | I11: =SUM(I3:I10) -> 0 | J11: =SUM(J3:J10) -> 0 | ... L11: =SUM(L3:L10) -> #DIV/0!
A12: Porcentaje | C12: =C11/$K$11 -> #DIV/0! | D12: =D11/$K$11 -> #DIV/0! | E12: =E11/$K$11 -> #DIV/0! | F12: =F11/$K$11 -> #DIV/0! | G12: =G11/$K$11 -> #DIV/0! | H12: =H11/$K$11 -> #DIV/0! | I12: =I11/$K$11 -> #DIV/0! | J12: =J11/$K$11 -> #DIV/0! | K12: =SUM(C12:J12) -> #DIV/0!
A13: Velocidad [m/s] | B13: Máxima
B14: Promedio
B15: Desv. Estándar
C17: Direccion | K17: Cant. Datos | L17: Porcentaje
C18: N | D18: NE | E18: E | F18: SE | G18: S | H18: SO | I18: O | J18: NO
A19: Rangos de Velocidad del Viento [m/s] | B19: =B$3 -> 0 | K19: =SUM(C19:J19) -> 0 | L19: =SUM(C19:J19)/$K$27 -> #DIV/0!
B20: =B$4 -> 0 | K20: =SUM(C20:J20) -> 0 | L20: =SUM(C20:J20)/$K$27 -> #DIV/0! | N20: =TEXT(EOMONTH(DATEVALUE(N4&"1"),0)+1,"mmmm") -> abril
B21: =B$5 -> 0 | K21: =SUM(C21:J21) -> 0 | L21: =SUM(C21:J21)/$K$27 -> #DIV/0!
B22: =B$6 -> 0 | K22: =SUM(C22:J22) -> 0 | L22: =SUM(C22:J22)/$K$27 -> #DIV/0!
B23: =B$7 -> 0 | K23: =SUM(C23:J23) -> 0 | L23: =SUM(C23:J23)/$K$27 -> #DIV/0!
B24: =B$8 -> 0 | K24: =SUM(C24:J24) -> 0 | L24: =SUM(C24:J24)/$K$27 -> #DIV/0!
B25: =B$9 -> 0 | K25: =SUM(C25:J25) -> 0 | L25: =SUM(C25:J25)/$K$27 -> #DIV/0!
B26: =B$10 -> 0 | K26: =SUM(C26:J26) -> 0 | L26: =SUM(C26:J26)/$K$27 -> #DIV/0!
A27: Cant. Datos | C27: =SUM(C19:C26) -> 0 | D27: =SUM(D19:D26) -> 0 | E27: =SUM(E19:E26) -> 0 | F27: =SUM(F19:F26) -> 0 | G27: =SUM(G19:G26) -> 0 | H27: =SUM(H19:H26) -> 0 | I27: =SUM(I19:I26) -> 0 | J27: =SUM(J19:J26) -> 0 | ... L27: =SUM(L19:L26) -> #DIV/0!
A28: Porcentaje | C28: =C27/$K$27 -> #DIV/0! | D28: =D27/$K$27 -> #DIV/0! | E28: =E27/$K$27 -> #DIV/0! | F28: =F27/$K$27 -> #DIV/0! | G28: =G27/$K$27 -> #DIV/0! | H28: =H27/$K$27 -> #DIV/0! | I28: =I27/$K$27 -> #DIV/0! | J28: =J27/$K$27 -> #DIV/0! | K28: =SUM(C28:J28) -> #DIV/0!
A29: Velocidad [m/s] | B29: Máxima
B30: Promedio
B31: Desv. Estándar
C33: Direccion | K33: Cant. Datos | L33: Porcentaje
C34: N | D34: NE | E34: E | F34: SE | G34: S | H34: SO | I34: O | J34: NO
A35: Rangos de Velocidad del Viento [m/s] | B35: =B$3 -> 0 | K35: =SUM(C35:J35) -> 0 | L35: =SUM(C35:J35)/$K$43 -> #DIV/0!
B36: =B$4 -> 0 | K36: =SUM(C36:J36) -> 0 | L36: =SUM(C36:J36)/$K$43 -> #DIV/0! | N36: =TEXT(EOMONTH(DATEVALUE(N20&"1"),0)+1,"mmmm") -> mayo
B37: =B$5 -> 0 | K37: =SUM(C37:J37) -> 0 | L37: =SUM(C37:J37)/$K$43 -> #DIV/0!
B38: =B$6 -> 0 | K38: =SUM(C38:J38) -> 0 | L38: =SUM(C38:J38)/$K$43 -> #DIV/0!
B39: =B$7 -> 0 | K39: =SUM(C39:J39) -> 0 | L39: =SUM(C39:J39)/$K$43 -> #DIV/0!
B40: =B$8 -> 0 | K40: =SUM(C40:J40) -> 0 | L40: =SUM(C40:J40)/$K$43 -> #DIV/0!
B41: =B$9 -> 0 | K41: =SUM(C41:J41) -> 0 | L41: =SUM(C41:J41)/$K$43 -> #DIV/0!
B42: =B$10 -> 0 | K42: =SUM(C42:J42) -> 0 | L42: =SUM(C42:J42)/$K$43 -> #DIV/0!
...

Sheet VALIDACIÓN_ERA5
A1: Indicador | B1: ERA5 | C1: ERA-A
A2: Cantidad de Datos
A3: Promedio Instrumento
A4: Promedio ERA5
A5: Sigma Instrumento
A6: Sigma ERA5
A7: MAE
A8: RMSE
A9: BIAS
A10: r
A11: R2(0,0)

Sheet EVENTOS-EXTREMOS-INST
A1: Norte | F1: Noreste | K1: Este | P1: Sureste | U1: Sur | Z1: Suroeste | AE1: Oeste | AJ1: Noroeste
A2: Método | B2: Fecha y Hora | C2: Vel. Viento [m/s] | D2: Dir. Viento [°] | F2: Método | G2: Fecha y Hora | H2: Vel. Viento [m/s] | I2: Dir. Viento [°] | K2: Método | L2: Fecha y Hora | M2: Vel. Viento [m/s] | N2: Dir. Viento [°] | P2: Método | Q2: Fecha y Hora | R2: Vel. Viento [m/s] | S2: Dir. Viento [°] | U2: Método | V2: Fecha y Hora | W2: Vel. Viento [m/s] | X2: Dir. Viento [°] | Z2: Método | AA2: Fecha y Hora | AB2: Vel. Viento [m/s] | AC2: Dir. Viento [°] | AE2: Método | AF2: Fecha y Hora | AG2: Vel. Viento [m/s] | AH2: Dir. Viento [°] | AJ2: Método | AK2: Fecha y Hora | AL2: Vel. Viento [m/s] | AM2: Dir. Viento [°]
A26: Cantidad POT | B26: =COUNTIF(A3:A24,"POT")+B28 -> 0 | F26: Cantidad POT | G26: =COUNTIF(F3:F24,"POT")+G28 -> 0 | K26: Cantidad POT | L26: =COUNTIF(K3:K24,"POT")+L28 -> 0 | P26: Cantidad POT | Q26: =COUNTIF(P3:P24,"POT")+Q28 -> 0 | U26: Cantidad POT | V26: =COUNTIF(U3:U24,"POT")+V28 -> 0 | Z26: Cantidad POT | AA26: =COUNTIF(Z3:Z24,"POT")+AA28 -> 0 | AE26: Cantidad POT | AF26: =COUNTIF(AE3:AE24,"POT")+AF28 -> 0 | AJ26: Cantidad POT | AK26: =COUNTIF(AJ3:AJ24,"POT")+AK28 -> 0
A27: Cantidad GEV | B27: =COUNTIF(A3:A24,"GEV")+B28 -> 0 | F27: Cantidad GEV | G27: =COUNTIF(F3:F24,"GEV")+G28 -> 0 | K27: Cantidad GEV | L27: =COUNTIF(K3:K24,"GEV")+L28 -> 0 | P27: Cantidad GEV | Q27: =COUNTIF(P3:P24,"GEV")+Q28 -> 0 | U27: Cantidad GEV | V27: =COUNTIF(U3:U24,"GEV")+V28 -> 0 | Z27: Cantidad GEV | AA27: =COUNTIF(Z3:Z24,"GEV")+AA28 -> 0 | AE27: Cantidad GEV | AF27: =COUNTIF(AE3:AE24,"GEV")+AF28 -> 0 | AJ27: Cantidad GEV | AK27: =COUNTIF(AJ3:AJ24,"GEV")+AK28 -> 0
A28: Ambos | B28: =COUNTIF(A3:A24,"POT + GEV") -> 0 | F28: Ambos | G28: =COUNTIF(F3:F24,"POT + GEV") -> 0 | K28: Ambos | L28: =COUNTIF(K3:K24,"POT + GEV") -> 0 | P28: Ambos | Q28: =COUNTIF(P3:P24,"POT + GEV") -> 0 | U28: Ambos | V28: =COUNTIF(U3:U24,"POT + GEV") -> 0 | Z28: Ambos | AA28: =COUNTIF(Z3:Z24,"POT + GEV") -> 0 | AE28: Ambos | AF28: =COUNTIF(AE3:AE24,"POT + GEV") -> 0 | AJ28: Ambos | AK28: =COUNTIF(AJ3:AJ24,"POT + GEV") -> 0
B30: POT | C30: GEV | G30: POT | H30: GEV | L30: POT | M30: GEV | Q30: POT | R30: GEV | V30: POT | W30: GEV | AA30: POT | AB30: GEV | AF30: POT | AG30: GEV | AK30: POT | AL30: GEV
A31: Máximo m/s | B31: =MAX(_xlfn.MAXIFS(C3:C24,A3:A24,"POT"),_xlfn.MAXIFS(C3:C24,A3:A24,"POT + GEV")) -> 0 | C31: =MAX(_xlfn.MAXIFS(C3:C24,A3:A24,"GEV"),_xlfn.MAXIFS(C3:C24,A3:A24,"POT + GEV")) -> 0 | F31: Máximo m/s | G31: =MAX(_xlfn.MAXIFS(H3:H24,F3:F24,"POT"),_xlfn.MAXIFS(H3:H24,F3:F24,"POT + GEV")) -> 0 | H31: =MAX(_xlfn.MAXIFS(H3:H24,F3:F24,"GEV"),_xlfn.MAXIFS(H3:H24,F3:F24,"POT + GEV")) -> 0 | K31: Máximo m/s | L31: =MAX(_xlfn.MAXIFS(M3:M24,K3:K24,"POT"),_xlfn.MAXIFS(M3:M24,K3:K24,"POT + GEV")) -> 0 | M31: =MAX(_xlfn.MAXIFS(M3:M24,K3:K24,"GEV"),_xlfn.MAXIFS(M3:M24,K3:K24,"POT + GEV")) -> 0 | P31: Máximo m/s | Q31: =MAX(_xlfn.MAXIFS(R3:R24,P3:P24,"POT"),_xlfn.MAXIFS(R3:R24,P3:P24,"POT + GEV")) -> 0 | R31: =MAX(_xlfn.MAXIFS(R3:R24,P3:P24,"GEV"),_xlfn.MAXIFS(R3:R24,P3:P24,"POT + GEV")) -> 0 | U31: Máximo m/s | V31: =MAX(_xlfn.MAXIFS(W3:W24,U3:U24,"POT"),_xlfn.MAXIFS(W3:W24,U3:U24,"POT + GEV")) -> 0 | W31: =MAX(_xlfn.MAXIFS(W3:W24,U3:U24,"GEV"),_xlfn.MAXIFS(W3:W24,U3:U24,"POT + GEV")) -> 0 | Z31: Máximo m/s | AA31: =MAX(_xlfn.MAXIFS(AB3:AB24,Z3:Z24,"POT"),_xlfn.MAXIFS(AB3:AB24,Z3:Z24,"POT + GEV")) -> 0 | AB31: =MAX(_xlfn.MAXIFS(AB3:AB24,Z3:Z24,"GEV"),_xlfn.MAXIFS(AB3:AB24,Z3:Z24,"POT + GEV")) -> 0 | AE31: Máximo m/s | AF31: =MAX(_xlfn.MAXIFS(AG3:AG24,AE3:AE24,"POT"),_xlfn.MAXIFS(AG3:AG24,AE3:AE24,"POT + GEV")) -> 0 | AG31: =MAX(_xlfn.MAXIFS(AG3:AG24,AE3:AE24,"GEV"),_xlfn.MAXIFS(AG3:AG24,AE3:AE24,"POT + GEV")) -> 0 | AJ31: Máximo m/s | AK31: =MAX(_xlfn.MAXIFS(AL3:AL24,AJ3:AJ24,"POT"),_xlfn.MAXIFS(AL3:AL24,AJ3:AJ24,"POT + GEV")) -> 0 | AL31: =MAX(_xlfn.MAXIFS(AL3:AL24,AJ3:AJ24,"GEV"),_xlfn.MAXIFS(AL3:AL24,AJ3:AJ24,"POT + GEV")) -> 0
A32: Mínimo m/s | B32: =MIN(C3:C24) -> 0 | C32: =MIN(_xlfn.MINIFS(C3:C24,A3:A24,"GEV"),_xlfn.MINIFS(C3:C24,A3:A24,"POT + GEV")) -> 0 | F32: Mínimo m/s | G32: =MIN(H3:H24) -> 0 | H32: =MIN(_xlfn.MINIFS(H3:H24,F3:F24,"GEV"),_xlfn.MINIFS(H3:H24,F3:F24,"POT + GEV")) -> 0 | K32: Mínimo m/s | L32: =MIN(M3:M24) -> 0 | M32: =MIN(_xlfn.MINIFS(M3:M24,K3:K24,"GEV"),_xlfn.MINIFS(M3:M24,K3:K24,"POT + GEV")) -> 0 | P32: Mínimo m/s | Q32: =MIN(R3:R24) -> 0 | R32: =MIN(_xlfn.MINIFS(R3:R24,P3:P24,"GEV"),_xlfn.MINIFS(R3:R24,P3:P24,"POT + GEV")) -> 0 | U32: Mínimo m/s | V32: =MIN(W3:W24) -> 0 | W32: =MIN(_xlfn.MINIFS(W3:W24,U3:U24,"GEV"),_xlfn.MINIFS(W3:W24,U3:U24,"POT + GEV")) -> 0 | Z32: Mínimo m/s | AA32: =MIN(AB3:AB24) -> 0 | AB32: =MIN(_xlfn.MINIFS(AB3:AB24,Z3:Z24,"GEV"),_xlfn.MINIFS(AB3:AB24,Z3:Z24,"POT + GEV")) -> 0 | AE32: Mínimo m/s | AF32: =MIN(AG3:AG24) -> 0 | AG32: =MIN(_xlfn.MINIFS(AG3:AG24,AE3:AE24,"GEV"),_xlfn.MINIFS(AG3:AG24,AE3:AE24,"POT + GEV")) -> 0 | AJ32: Mínimo m/s | AK32: =MIN(AL3:AL24) -> 0 | AL32: =MIN(_xlfn.MINIFS(AL3:AL24,AJ3:AJ24,"GEV"),_xlfn.MINIFS(AL3:AL24,AJ3:AJ24,"POT + GEV")) -> 0
A33: Promedio m/s | B33: =(SUMIF(A3:A24,"POT",C3:C24)+SUMIF(A3:A24,"POT + GEV",C3:C24))/(COUNTIF(A3:A24,"POT")+COUNTIF(A3:A24,"POT + GEV")) -> #DIV/0! | C33: =(SUMIF(A3:A24,"GEV",C3:C24)+SUMIF(A3:A24,"POT + GEV",C3:C24))/(COUNTIF(A3:A24,"GEV")+COUNTIF(A3:A24,"POT + GEV")) -> #DIV/0! | F33: Promedio m/s | G33: =(SUMIF(F3:F24,"POT",H3:H24)+SUMIF(F3:F24,"POT + GEV",H3:H24))/(COUNTIF(F3:F24,"POT")+COUNTIF(F3:F24,"POT + GEV")) -> #DIV/0! | H33: =(SUMIF(F3:F24,"GEV",H3:H24)+SUMIF(F3:F24,"POT + GEV",H3:H24))/(COUNTIF(F3:F24,"GEV")+COUNTIF(F3:F24,"POT + GEV")) -> #DIV/0! | K33: Promedio m/s | L33: =(SUMIF(K3:K24,"POT",M3:M24)+SUMIF(K3:K24,"POT + GEV",M3:M24))/(COUNTIF(K3:K24,"POT")+COUNTIF(K3:K24,"POT + GEV")) -> #DIV/0! | M33: =(SUMIF(K3:K24,"GEV",M3:M24)+SUMIF(K3:K24,"POT + GEV",M3:M24))/(COUNTIF(K3:K24,"GEV")+COUNTIF(K3:K24,"POT + GEV")) -> #DIV/0! | P33: Promedio m/s | Q33: =(SUMIF(P3:P24,"POT",R3:R24)+SUMIF(P3:P24,"POT + GEV",R3:R24))/(COUNTIF(P3:P24,"POT")+COUNTIF(P3:P24,"POT + GEV")) -> #DIV/0! | R33: =(SUMIF(P3:P24,"GEV",R3:R24)+SUMIF(P3:P24,"POT + GEV",R3:R24))/(COUNTIF(P3:P24,"GEV")+COUNTIF(P3:P24,"POT + GEV")) -> #DIV/0! | U33: Promedio m/s | V33: =(SUMIF(U3:U24,"POT",W3:W24)+SUMIF(U3:U24,"POT + GEV",W3:W24))/(COUNTIF(U3:U24,"POT")+COUNTIF(U3:U24,"POT + GEV")) -> #DIV/0! | W33: =(SUMIF(U3:U24,"GEV",W3:W24)+SUMIF(U3:U24,"POT + GEV",W3:W24))/(COUNTIF(U3:U24,"GEV")+COUNTIF(U3:U24,"POT + GEV")) -> #DIV/0! | Z33: Promedio m/s | AA33: =(SUMIF(Z3:Z24,"POT",AB3:AB24)+SUMIF(Z3:Z24,"POT + GEV",AB3:AB24))/(COUNTIF(Z3:Z24,"POT")+COUNTIF(Z3:Z24,"POT + GEV")) -> #DIV/0! | AB33: =(SUMIF(Z3:Z24,"GEV",AB3:AB24)+SUMIF(Z3:Z24,"POT + GEV",AB3:AB24))/(COUNTIF(Z3:Z24,"GEV")+COUNTIF(Z3:Z24,"POT + GEV")) -> #DIV/0! | AE33: Promedio m/s | AF33: =(SUMIF(AE3:AE24,"POT",AG3:AG24)+SUMIF(AE3:AE24,"POT + GEV",AG3:AG24))/(COUNTIF(AE3:AE24,"POT")+COUNTIF(AE3:AE24,"POT + GEV")) -> #DIV/0! | AG33: =(SUMIF(AE3:AE24,"GEV",AG3:AG24)+SUMIF(AE3:AE24,"POT + GEV",AG3:AG24))/(COUNTIF(AE3:AE24,"GEV")+COUNTIF(AE3:AE24,"POT + GEV")) -> #DIV/0! | AJ33: Promedio m/s | AK33: =(SUMIF(AJ3:AJ24,"POT",AL3:AL24)+SUMIF(AJ3:AJ24,"POT + GEV",AL3:AL24))/(COUNTIF(AJ3:AJ24,"POT")+COUNTIF(AJ3:AJ24,"POT + GEV")) -> #DIV/0! | AL33: =(SUMIF(AJ3:AJ24,"GEV",AL3:AL24)+SUMIF(AJ3:AJ24,"POT + GEV",AL3:AL24))/(COUNTIF(AJ3:AJ24,"GEV")+COUNTIF(AJ3:AJ24,"POT + GEV")) -> #DIV/0!
B37: Norte | C37: Noreste | D37: Este | E37: Sureste | F37: Sur | G37: Suroeste | H37: Oeste | I37: Noroeste
A38: Máximo m/s | B38: =B31 -> 0 | C38: =G31 -> 0 | D38: =L31 -> 0 | E38: =Q31 -> 0 | F38: =V31 -> 0 | G38: =AA31 -> 0 | H38: =AF31 -> 0 | I38: =AK31 -> 0
A39: Mínimo m/s | B39: =B32 -> 0 | C39: =G32 -> 0 | D39: =L32 -> 0 | E39: =Q32 -> 0 | F39: =V32 -> 0 | G39: =AA32 -> 0 | H39: =AF32 -> 0 | I39: =AK32 -> 0
A40: Promedio m/s | B40: =B33 -> #DIV/0! | C40: =G33 -> #DIV/0! | D40: =L33 -> #DIV/0! | E40: =Q33 -> #DIV/0! | F40: =V33 -> #DIV/0! | G40: =AA33 -> #DIV/0! | H40: =AF33 -> #DIV/0! | I40: =AK33 -> #DIV/0!

Sheet PERIODO_RETORNO_INST
A1: Tr [años] | B1: Ajuste | C1: Norte | E1: Noreste | G1: Este | I1: Sureste | K1: Sur | M1: Suroeste | O1: Oeste | Q1: Noroeste | T1: Dirección | U1: Tr 50 años
C2: Vel.viento [m/s] | D2: Dir.viento [°] | E2: Vel.viento [m/s] | F2: Dir.viento [°] | G2: Vel.viento [m/s] | H2: Dir.viento [°] | I2: Vel.viento [m/s] | J2: Dir.viento [°] | K2: Vel.viento [m/s] | L2: Dir.viento [°] | M2: Vel.viento [m/s] | N2: Dir.viento [°] | O2: Vel.viento [m/s] | P2: Dir.viento [°] | Q2: Vel.viento [m/s] | R2: Dir.viento [°] | U2: Vel.viento [m/s] | V2: Dir.viento [°]
A3: 2 | B3: central | T3: N | U3: =C13 -> 0 | V3: =D13 -> 0 | X3: Dirección | Y3: Variable | Z3: Tr 10 años | AC3: Tr 50 años
B4: máx (90%) | T4: NE | U4: =E13 -> 0 | V4: =F13 -> 0 | Z4: central | AA4: máx (90%) | AB4: min (90%) | AC4: central | AD4: máx (90%) | AE4: min (90%)
B5: min (90%) | T5: E | U5: =G13 -> 0 | V5: =H13 -> 0 | X5: N | Y5: V [m/s] | Z5: =C25 -> 0 | AA5: =+C26 -> 0 | AB5: =+C27 -> 0 | AC5: =+C28 -> 0 | AD5: =+C29 -> 0 | AE5: =+C30 -> 0
A6: 10 | B6: central | T6: SE | U6: =I13 -> 0 | V6: =J13 -> 0 | Y6: D [°] | Z6: =D25 -> 0 | AA6: =+D26 -> 0 | AB6: =+D27 -> 0 | AC6: =+D28 -> 0 | AD6: =+D29 -> 0 | AE6: =+D30 -> 0
B7: máx (90%) | T7: S | U7: =K13 -> 0 | V7: =L13 -> 0 | X7: NE | Y7: V [m/s] | Z7: =+E25 -> 0 | AA7: =+E26 -> 0 | AB7: =+E27 -> 0 | AC7: =+E28 -> 0 | AD7: =+E29 -> 0 | AE7: =+E30 -> 0
B8: min (90%) | T8: SO | U8: =M13 -> 0 | V8: =N13 -> 0 | Y8: D [°] | Z8: =+F25 -> 0 | AA8: =+F26 -> 0 | AB8: =+F27 -> 0 | AC8: =+F28 -> 0 | AD8: =+F29 -> 0 | AE8: =+F30 -> 0
A9: 25 | B9: central | T9: O | U9: =O13 -> 0 | V9: =P13 -> 0 | X9: E | Y9: V [m/s] | Z9: =+G25 -> 0 | AA9: =+G26 -> 0 | AB9: =+G27 -> 0 | AC9: =+G28 -> 0 | AD9: =+G29 -> 0 | AE9: =+G30 -> 0
B10: máx (90%) | T10: NO | U10: =Q13 -> 0 | V10: =R13 -> 0 | Y10: D [°] | Z10: =+H25 -> 0 | AA10: =+H26 -> 0 | AB10: =+H27 -> 0 | AC10: =+H28 -> 0 | AD10: =+H29 -> 0 | AE10: =+H30 -> 0
B11: min (90%) | T11: Datos asociados a banda superior de un intervalo de confianza al 90% | X11: SE | Y11: V [m/s] | Z11: =+I25 -> 0 | AA11: =+I26 -> 0 | AB11: =+I27 -> 0 | AC11: =+I28 -> 0 | AD11: =+I29 -> 0 | AE11: =+I30 -> 0
A12: 50 | B12: central | Y12: D [°] | Z12: =+J25 -> 0 | AA12: =+J26 -> 0 | AB12: =+J27 -> 0 | AC12: =+J28 -> 0 | AD12: =+J29 -> 0 | AE12: =+J30 -> 0
B13: máx (90%) | X13: S | Y13: V [m/s] | Z13: =+K25 -> 0 | AA13: =+K26 -> 0 | AB13: =+K27 -> 0 | AC13: =+K28 -> 0 | AD13: =+K29 -> 0 | AE13: =+K30 -> 0
B14: min (90%) | Y14: D [°] | Z14: =+L25 -> 0 | AA14: =+L26 -> 0 | AB14: =+L27 -> 0 | AC14: =+L28 -> 0 | AD14: =+L29 -> 0 | AE14: =+L30 -> 0
A15: 75 | B15: central | X15: SO | Y15: V [m/s] | Z15: =+M25 -> 0 | AA15: =+M26 -> 0 | AB15: =+M27 -> 0 | AC15: =+M28 -> 0 | AD15: =+M29 -> 0 | AE15: =+M30 -> 0
B16: máx (90%) | Y16: D [°] | Z16: =+N25 -> 0 | AA16: =+N26 -> 0 | AB16: =+N27 -> 0 | AC16: =+N28 -> 0 | AD16: =+N29 -> 0 | AE16: =+N30 -> 0
B17: min (90%) | X17: O | Y17: V [m/s] | Z17: =+O25 -> 0 | AA17: =+O26 -> 0 | AB17: =+O27 -> 0 | AC17: =+O28 -> 0 | AD17: =+O29 -> 0 | AE17: =+O30 -> 0
A18: 100 | B18: central | Y18: D [°] | Z18: =+P25 -> 0 | AA18: =+P26 -> 0 | AB18: =+P27 -> 0 | AC18: =+P28 -> 0 | AD18: =+P29 -> 0 | AE18: =+P30 -> 0
B19: máx (90%) | X19: NO | Y19: V [m/s] | Z19: =+Q25 -> 0 | AA19: =+Q26 -> 0 | AB19: =+Q27 -> 0 | AC19: =+Q28 -> 0 | AD19: =+Q29 -> 0 | AE19: =+Q30 -> 0
B20: min (90%) | Y20: D [°] | Z20: =+R25 -> 0 | AA20: =+R26 -> 0 | AB20: =+R27 -> 0 | AC20: =+R28 -> 0 | AD20: =+R29 -> 0 | AE20: =+R30 -> 0
A23: Tr [años] | B23: Ajuste | C23: Norte | E23: Noreste | G23: Este | I23: Sureste | K23: Sur | M23: Suroeste | O23: Oeste | Q23: Noroeste | X23: Parámetros de Diseño Asociados a Viento
C24: V [m/s] | D24: D [°] | E24: V [m/s] | F24: D [°] | G24: V [m/s] | H24: D [°] | I24: V [m/s] | J24: D [°] | K24: V [m/s] | L24: D [°] | M24: V [m/s] | N24: D [°] | O24: V [m/s] | P24: D [°] | Q24: V [m/s] | R24: D [°] | X24: Dirección | Y24: Variable | Z24: Tr 10 años | AC24: Tr 50 años
A25: 10 | B25: central | C25: {=C6:C8} -> 0 | D25: {=D6:D8} -> 0 | E25: {=E6:E8} -> 0 | F25: {=F6:F8} -> 0 | G25: {=G6:G8} -> 0 | H25: {=H6:H8} -> 0 | I25: {=I6:I8} -> 0 | J25: {=J6:J8} -> 0 | ... R25: {=R6:R8} -> 0 | Z25: central | AA25: máx (90%) | AB25: min (90%) | AC25: central | AD25: máx (90%) | AE25: min (90%)
B26: máx (90%) | C26: 0 | D26: 0 | E26: 0 | F26: 0 | G26: 0 | H26: 0 | I26: 0 | J26: 0 | K26: 0 | L26: 0 | M26: 0 | N26: 0 | O26: 0 | P26: 0 | Q26: 0 | R26: 0 | X26: N | Y26: V [m/s] | Z26: =Z5 -> 0 | AA26: =AA5 -> 0 | AB26: =AB5 -> 0 | AC26: =AC5 -> 0 | AD26: =AD5 -> 0 | AE26: =AE5 -> 0
B27: min (90%) | C27: 0 | D27: 0 | E27: 0 | F27: 0 | G27: 0 | H27: 0 | I27: 0 | J27: 0 | K27: 0 | L27: 0 | M27: 0 | N27: 0 | O27: 0 | P27: 0 | Q27: 0 | R27: 0 | X27: (0°) | AA27: =AA6 -> 0 | AB27: =AB6 -> 0 | AC27: =AC6 -> 0 | AD27: =AD6 -> 0 | AE27: =AE6 -> 0
A28: 50 | B28: central | C28: {=C12:C14} -> 0 | D28: {=D12:D14} -> 0 | E28: {=E12:E14} -> 0 | F28: {=F12:F14} -> 0 | G28: {=G12:G14} -> 0 | H28: {=H12:H14} -> 0 | I28: {=I12:I14} -> 0 | J28: {=J12:J14} -> 0 | ... R28: {=R12:R14} -> 0 | X28: NE | Y28: V [m/s] | Z28: =Z7 -> 0 | AA28: =AA7 -> 0 | AB28: =AB7 -> 0 | AC28: =AC7 -> 0 | AD28: =AD7 -> 0 | AE28: =AE7 -> 0
B29: máx (90%) | C29: 0 | D29: 0 | E29: 0 | F29: 0 | G29: 0 | H29: 0 | I29: 0 | J29: 0 | K29: 0 | L29: 0 | M29: 0 | N29: 0 | O29: 0 | P29: 0 | Q29: 0 | R29: 0 | X29: (45°) | Y29: D [°] | Z29: =Z8 -> 0 | AA29: =AA8 -> 0 | AB29: =AB8 -> 0 | AC29: =AC8 -> 0 | AD29: =AD8 -> 0 | AE29: =AE8 -> 0
B30: min (90%) | C30: 0 | D30: 0 | E30: 0 | F30: 0 | G30: 0 | H30: 0 | I30: 0 | J30: 0 | K30: 0 | L30: 0 | M30: 0 | N30: 0 | O30: 0 | P30: 0 | Q30: 0 | R30: 0 | X30: E | Y30: V [m/s] | Z30: =Z9 -> 0 | AA30: =AA9 -> 0 | AB30: =AB9 -> 0 | AC30: =AC9 -> 0 | AD30: =AD9 -> 0 | AE30: =AE9 -> 0
X31: (90°) | Y31: D [°] | Z31: =Z10 -> 0 | AA31: =AA10 -> 0 | AB31: =AB10 -> 0 | AC31: =AC10 -> 0 | AD31: =AD10 -> 0 | AE31: =AE10 -> 0
X32: SE | Y32: V [m/s] | Z32: =Z11 -> 0 | AA32: =AA11 -> 0 | AB32: =AB11 -> 0 | AC32: =AC11 -> 0 | AD32: =AD11 -> 0 | AE32: =AE11 -> 0
X33: (135°) | Y33: D [°] | Z33: =Z12 -> 0 | AA33: =AA12 -> 0 | AB33: =AB12 -> 0 | AC33: =AC12 -> 0 | AD33: =AD12 -> 0 | AE33: =AE12 -> 0
X34: S | Y34: V [m/s] | Z34: =Z13 -> 0 | AA34: =AA13 -> 0 | AB34: =AB13 -> 0 | AC34: =AC13 -> 0 | AD34: =AD13 -> 0 | AE34: =AE13 -> 0
X35: (180°) | Y35: D [°] | Z35: =Z14 -> 0 | AA35: =AA14 -> 0 | AB35: =AB14 -> 0 | AC35: =AC14 -> 0 | AD35: =AD14 -> 0 | AE35: =AE14 -> 0
X36: SO | Y36: V [m/s] | Z36: =Z15 -> 0 | AA36: =AA15 -> 0 | AB36: =AB15 -> 0 | AC36: =AC15 -> 0 | AD36: =AD15 -> 0 | AE36: =AE15 -> 0
X37: (225°) | Y37: D [°] | Z37: =Z16 -> 0 | AA37: =AA16 -> 0 | AB37: =AB16 -> 0 | AC37: =AC16 -> 0 | AD37: =AD16 -> 0 | AE37: =AE16 -> 0
X38: O | Y38: V [m/s] | Z38: =Z17 -> 0 | AA38: =AA17 -> 0 | AB38: =AB17 -> 0 | AC38: =AC17 -> 0 | AD38: =AD17 -> 0 | AE38: =AE17 -> 0
X39: (270°) | Y39: D [°] | Z39: =Z18 -> 0 | AA39: =AA18 -> 0 | AB39: =AB18 -> 0 | AC39: =AC18 -> 0 | AD39: =AD18 -> 0 | AE39: =AE18 -> 0
X40: NO | Y40: V [m/s] | Z40: =Z19 -> 0 | AA40: =AA19 -> 0 | AB40: =AB19 -> 0 | AC40: =AC19 -> 0 | AD40: =AD19 -> 0 | AE40: =AE19 -> 0
X41: (315°) | Y41: D [°] | Z41: =Z20 -> 0 | AA41: =AA20 -> 0 | AB41: =AB20 -> 0 | AC41: =AC20 -> 0 | AD41: =AD20 -> 0 | AE41: =AE20 -> 0

Sheet Hoja1
A1: Parámetros de Diseño Asociados a Viento (m/s)
A2: Dirección | B2: Tr 10 años | E2: Tr 50 años
B3: central | C3: máx (90%) | D3: min (90%) | E3: central | F3: máx (90%) | G3: min (90%)
A4: N (0°) | B4: =PERIODO_RETORNO_INST!Z26 -> 0 | C4: =PERIODO_RETORNO_INST!AA26 -> 0 | D4: =PERIODO_RETORNO_INST!AB26 -> 0 | E4: =PERIODO_RETORNO_INST!AC26 -> 0 | F4: =PERIODO_RETORNO_INST!AD26 -> 0 | G4: =PERIODO_RETORNO_INST!AE26 -> 0
A5: NE (45°) | B5: =PERIODO_RETORNO_INST!Z28 -> 0 | C5: =PERIODO_RETORNO_INST!AA28 -> 0 | D5: =PERIODO_RETORNO_INST!AB28 -> 0 | E5: =PERIODO_RETORNO_INST!AC28 -> 0 | F5: =PERIODO_RETORNO_INST!AD28 -> 0 | G5: =PERIODO_RETORNO_INST!AE28 -> 0
A6: E (90°) | B6: =PERIODO_RETORNO_INST!Z30 -> 0 | C6: =PERIODO_RETORNO_INST!AA30 -> 0 | D6: =PERIODO_RETORNO_INST!AB30 -> 0 | E6: =PERIODO_RETORNO_INST!AC30 -> 0 | F6: =PERIODO_RETORNO_INST!AD30 -> 0 | G6: =PERIODO_RETORNO_INST!AE30 -> 0
A7: SE (135°) | B7: =PERIODO_RETORNO_INST!Z32 -> 0 | C7: =PERIODO_RETORNO_INST!AA32 -> 0 | D7: =PERIODO_RETORNO_INST!AB32 -> 0 | E7: =PERIODO_RETORNO_INST!AC32 -> 0 | F7: =PERIODO_RETORNO_INST!AD32 -> 0 | G7: =PERIODO_RETORNO_INST!AE32 -> 0
A8: S (180°) | B8: =PERIODO_RETORNO_INST!Z34 -> 0 | C8: =PERIODO_RETORNO_INST!AA34 -> 0 | D8: =PERIODO_RETORNO_INST!AB34 -> 0 | E8: =PERIODO_RETORNO_INST!AC34 -> 0 | F8: =PERIODO_RETORNO_INST!AD34 -> 0 | G8: =PERIODO_RETORNO_INST!AE34 -> 0
A9: SO (225°) | B9: =PERIODO_RETORNO_INST!Z36 -> 0 | C9: =PERIODO_RETORNO_INST!AA36 -> 0 | D9: =PERIODO_RETORNO_INST!AB36 -> 0 | E9: =PERIODO_RETORNO_INST!AC36 -> 0 | F9: =PERIODO_RETORNO_INST!AD36 -> 0 | G9: =PERIODO_RETORNO_INST!AE36 -> 0
A10: O (270°) | B10: =PERIODO_RETORNO_INST!Z38 -> 0 | C10: =PERIODO_RETORNO_INST!AA38 -> 0 | D10: =PERIODO_RETORNO_INST!AB38 -> 0 | E10: =PERIODO_RETORNO_INST!AC38 -> 0 | F10: =PERIODO_RETORNO_INST!AD38 -> 0 | G10: =PERIODO_RETORNO_INST!AE38 -> 0
A11: NO (315°) | B11: =PERIODO_RETORNO_INST!Z40 -> 0 | C11: =PERIODO_RETORNO_INST!AA40 -> 0 | D11: =PERIODO_RETORNO_INST!AB40 -> 0 | E11: =PERIODO_RETORNO_INST!AC40 -> 0 | F11: =PERIODO_RETORNO_INST!AD40 -> 0 | G11: =PERIODO_RETORNO_INST!AE40 -> 0

Sheet PERIODO_RETORNO
A1: Parámetros de Diseño Asociados a Viento (m/s)
A2: Dirección | B2: Tr 10 años | E2: Tr 50 años
B3: central | C3: máx (90%) | D3: min (90%) | E3: central | F3: máx (90%) | G3: min (90%)
A4: N (0°)
A5: NE (45°)
A6: E (90°)
A7: SE (135°)
A8: S (180°)
A9: SO (225°)
A10: O (270°)
A11: NO (315°)
